Workbook

Sheet 1000_заявлений
A1: Column1 | B1: proba | C1: weighted_ext_score | D1: ext_source_3 | E1: ext_source_2 | F1: days_registration | G1: days_birth | H1: days_id_publish | I1: annuity_to_income_proportion | J1: interest_rate | K1: days_employed | L1: amt_annuity
A2: 0 | B2: 0.3327641206132701 | C2: 0.3365582763192264 | D2: 0.5100895 | E2: 0.46882638 | F2: -13252.0 | G2: -24248 | H2: -4638 | I2: 0.1302666666666666 | J2: 10.286382966226505 | K2: 365243 | L2: 17586.0
A3: 1 | B3: 0.1647667168806656 | C3: 0.6567637677860341 | D3: 0.8128226 | E3: 0.5851475 | F3: -2832.0 | G3: -13436 | H3: -5901 | I3: 0.0845428571428571 | J3: 5.262763196925069 | K3: -193 | L3: 13315.5
A4: 2 | B4: 0.20927631496119886 | C4: 0.660740637551938 | D4: 0.66585493 | E4: 0.41578013 | F4: -9257.0 | G4: -20066 | H4: -3474 | I4: 0.1854571428571428 | J4: 16.031722325569575 | K4: -153 | L4: 29209.5
A5: 3 | B5: 0.666125971080747 | C5: 0.2255135445531536 | D5: 0.53527623 | E5: 0.26651978 | F5: -4957.0 | G5: -16953 | H5: -510 | I5: 0.20924 | J5: 0.9263040911869692 | K5: -4400 | L5: 23539.5
A6: 4 | B6: 0.2515486161931931 | C6: 0.503130800946699 | D6: 0.79226446 | E6: 0.6677294 | F6: -3208.0 | G6: -9028 | H6: -1695 | I6: 0.16545 | J6: 2.38451772076127 | K6: -1056 | L6: 44671.5
A7: 5 | B7: 0.3929445276810413 | C7: 0.4181608909767079 | D7: 0.57620883 | E7: 0.6466736 | F7: -1976.0 | G7: -17356 | H7: -910 | I7: 0.2667428571428571 | J7: 1.557296632421834 | K7: -1897 | L7: 42012.0
A8: 6 | B8: 0.6560773604026818 | C8: 0.2276690267229509 | D8: 0.6212263 | E8: 0.0092263855 | F8: -644.0 | G8: -23233 | H8: -4172 | I8: 0.23025 | J8: 1.826989682865876 | K8: -881 | L8: 33156.0
A9: 7 | B9: 0.4515510006965235 | C9: 0.3568197941517482 | D9: 0.4632753 | E9: 0.583485 | F9: -7970.0 | G9: -18719 | H9: -2278 | I9: 0.1711 | J9: 5.373077905188306 | K9: -9768 | L9: 15399.0
A10: 8 | B10: 0.19779021601467595 | C10: 0.4978209706807676 | D10: 0.7517237 | E10: 0.6965612 | F10: -2639.0 | G10: -14817 | H10: -4892 | I10: 0.0365466666666666 | J10: 5.041883844694683 | K10: -648 | L10: 12334.5
A11: 9 | B11: 0.42960217972997594 | C11: 0.3558477455899367 | D11: 0.7463002 | E11: 0.2649283 | F11: -4041.0 | G11: -19962 | H11: -3519 | I11: 0.10825 | J11: 0.9643634185798168 | K11: -6395 | L11: 9742.5
A12: 10 | B12: 0.7824464951084797 | C12: 0.3505918427475524 | D12: 0.21396685 | E12: 0.25164637 | F12: -1827.0 | G12: -14908 | H12: -1827 | I12: 0.3266666666666666 | J12: 3.668589070030981 | K12: -125 | L12: 22050.0
A13: 11 | B13: 0.6863646085140306 | C13: 0.3443711466298985 | D13: 0.30314636 | E13: 0.41661963 | F13: -3833.0 | G13: -9400 | H13: -1953 | I13: 0.2590222222222222 | J13: 2.724447230294258 | K13: -536 | L13: 52452.0
... A1001: 999 | B1001: 0.22696464742336545 | C1001: 0.4074960304429795 | D1001: 0.7688076 | E1001: 0.39905664 | F1001: -11581.0 | G1001: -24822 | H1001: -4058 | I1001: 0.19735 | J1001: 20.37251547594485 | K1001: -1595 | L1001: 17761.5

Sheet Расчет суммы займов 1
B1: min_sum | C1: 20000 | D1: proba_less_for_sum | N1: condition1 | O1: 0.7 | P1: 0.5 | Q1: -2000 | S1: 25 | T1: 20 | X1: Количество заявок | AC1: Сумма издержек | AD1: Сумма прибыли | AE1: Сумма дохода | AF1: Прибыль/издержки
B2: max_sum | C2: 500000 | D2: 0.1 | N2: coef1 | O2: 1.2 | P2: 0.8 | Q2: 1.2 | S2: 0.7 | T2: 0.8 | X2: =COUNT(Данные[id]) -> 1000 | AC2: =SUM(AC$7:AC$34) -> -10310856 | AD2: =SUM(AD$7:AD$34) -> 2050197.2 | AE2: =SUM(AE$7:AE$34) -> -8260658.4 | AF2: =ABS(AD2/AC2) -> 0.19883871
C3: 300000 | D3: 0.2 | N3: condition2 | O3: 0.3 | P3: 0.2 | Q3: -365 | S3: 50 | X3: Издержки | Y3: 1
C4: 100000 | D4: =C6 -> 0.3 | N4: coef2 | O4: 0.8 | P4: 1.2 | Q4: 0.7 | S4: 1.05 | X4: Прибыль | Y4: 0.05
N5: condition3 | Q5: 0
B6: threshold | C6: 0.3 | N6: coef3 | Q6: 0.5
A7: id | B7: proba | C7: weighted_ext_score | D7: ext_source_3 | E7: ext_source_2 | F7: days_registration | G7: days_birth | H7: days_id_publish | I7: annuity_to_income_proportion | J7: interest_rate | K7: days_employed | L7: amt_annuity | M7: Проверка отказа | N7: Базовая сумма | O7: weighted_ext_score2 | P7: annuity_to_income | Q7: days_employed3 | R7: age_years | S7: days_birth4 | T7: interest_rate | U7: Минимум 20000 | V7: Итоговая сумма | X7: Уникальные суммы | Y7: Количество выдачей в группе | Z7: Средняя вероятность дефолта в группе | AA7: Дефолт | AB7: Вернут | AC7: Издержки | AD7: Прибыль | AE7: Доход
A8: ='1000_заявлений'!A2 -> 0 | B8: =VALUE(SUBSTITUTE('1000_заявлений'!B2, ".", ",")) -> 0.33276412 | C8: =VALUE(SUBSTITUTE('1000_заявлений'!C2, ".", ",")) -> 0.33655828 | D8: =VALUE(SUBSTITUTE('1000_заявлений'!D2, ".", ",")) -> 0.5100895 | E8: =VALUE(SUBSTITUTE('1000_заявлений'!E2, ".", ",")) -> 0.46882638 | F8: =VALUE(SUBSTITUTE('1000_заявлений'!F2, ".", ",")) -> -13252 | G8: =VALUE(SUBSTITUTE('1000_заявлений'!G2, ".", ",")) -> -24248 | H8: =VALUE(SUBSTITUTE('1000_заявлений'!H2, ".", ",")) -> -4638 | I8: =VALUE(SUBSTITUTE('1000_заявлений'!I2, ".", ",")) -> 0.13026667 | ... L8: =VALUE(SUBSTITUTE('1000_заявлений'!L2, ".", ",")) -> 17586 | M8: =IF(Данные[[#This Row],[proba]]>$C$6, "отказ", "одобрение") -> отказ | N8: =IF(Данные[[#This Row],[proba]]<$D$2,$C$2,IF(Данные[[#This Row],[proba]]<$D$3,$C$3,IF(Данные[[#This Row],[proba]]>$C$6,0,$C$4))) -> 0 | O8: =IF(Данные[[#This Row],[weighted_ext_score]]>$O$1,MIN(Данные[[#This Row],[Базовая сумма]]*$O$2,$C$2),IF(Данные[[#This Row],[weighted_ext_score]]<$O$3,Данные[[#This Row],[Базовая сумма]]*$O$4,N8)) -> 0 | P8: =IF(Данные[[#This Row],[ annuity_to_income_proportion]]>$P$1,Данные[[#This Row],[weighted_ext_score2]]*$P$2,IF(Данные[[#This Row],[ annuity_to_income_proportion]]<$P$3,MIN(Данные[[#This Row],[weighted_ext_score2]]*$P$4,$C$2),Данные[[#This Row],[weighted_ext_score2]])) -> 0 | Q8: =IF(Данные[[#This Row],[days_employed]]<$Q$1,MIN(Данные[[#This Row],[annuity_to_income]]*$Q$2,$C$2),IF(Данные[[#This Row],[days_employed]]<$Q$3,Данные[[#This Row],[annuity_to_income]]*$Q$4,IF(Данные[[#This Row],[days_employed]]=$Q$5,Данные[[#This Row],[annuity_to_income]]*$Q$6,Данные[[#This Row],[annuity_to_income]]))) -> 0 | R8: =ABS(Данные[[#This Row],[days_birth]])/365.2425 -> 66.388769 | S8: =IF(Данные[[#This Row],[age_years]]<$S$1,Данные[[#This Row],[days_employed3]]*$S$2,IF(Данные[[#This Row],[age_years]]>$S$3,MIN(Данные[[#This Row],[days_employed3]]*$S$4,$C$2),Данные[[#This Row],[days_employed3]])) -> 0 | T8: =IF(Данные[[#This Row],[ interest_rate]]>$T$1,Данные[[#This Row],[days_birth4]]*$T$2,Данные[[#This Row],[days_birth4]]) -> 0 | U8: =IF(Данные[[#This Row],[Проверка отказа]]="отказ",0,MAX(Данные[[#This Row],[interest_rate]],$C$1)) -> 0 | V8: =MROUND(Данные[[#This Row],[Минимум 20000]], 100) -> 0 | X8: {=_xlfn.UNIQUE(Данные[Итоговая сумма])} -> 0 | Y8: =COUNTIF(Данные[Итоговая сумма], X8) -> 729 | Z8: =AVERAGEIF(Данные[Итоговая сумма], X8, Данные[proba]) -> 0.5282267 | AA8: =Y8*Z8 -> 385.07726 | AB8: =Y8-AA8 -> 343.92274 | AC8: =-X8*AA8*$Y$3 -> 0 | AD8: =X8*AB8*$Y$4 -> 0 | AE8: =AD8+AC8 -> 0
A9: ='1000_заявлений'!A3 -> 1 | B9: =VALUE(SUBSTITUTE('1000_заявлений'!B3, ".", ",")) -> 0.16476672 | C9: =VALUE(SUBSTITUTE('1000_заявлений'!C3, ".", ",")) -> 0.65676377 | D9: =VALUE(SUBSTITUTE('1000_заявлений'!D3, ".", ",")) -> 0.8128226 | E9: =VALUE(SUBSTITUTE('1000_заявлений'!E3, ".", ",")) -> 0.5851475 | F9: =VALUE(SUBSTITUTE('1000_заявлений'!F3, ".", ",")) -> -2832 | G9: =VALUE(SUBSTITUTE('1000_заявлений'!G3, ".", ",")) -> -13436 | H9: =VALUE(SUBSTITUTE('1000_заявлений'!H3, ".", ",")) -> -5901 | I9: =VALUE(SUBSTITUTE('1000_заявлений'!I3, ".", ",")) -> 0.084542857 | ... L9: =VALUE(SUBSTITUTE('1000_заявлений'!L3, ".", ",")) -> 13315.5 | M9: =IF(Данные[[#This Row],[proba]]>$C$6, "отказ", "одобрение") -> одобрение | N9: =IF(Данные[[#This Row],[proba]]<$D$2,$C$2,IF(Данные[[#This Row],[proba]]<$D$3,$C$3,IF(Данные[[#This Row],[proba]]>$C$6,0,$C$4))) -> 300000 | O9: =IF(Данные[[#This Row],[weighted_ext_score]]>$O$1,MIN(Данные[[#This Row],[Базовая сумма]]*$O$2,$C$2),IF(Данные[[#This Row],[weighted_ext_score]]<$O$3,Данные[[#This Row],[Базовая сумма]]*$O$4,N9)) -> 300000 | P9: =IF(Данные[[#This Row],[ annuity_to_income_proportion]]>$P$1,Данные[[#This Row],[weighted_ext_score2]]*$P$2,IF(Данные[[#This Row],[ annuity_to_income_proportion]]<$P$3,MIN(Данные[[#This Row],[weighted_ext_score2]]*$P$4,$C$2),Данные[[#This Row],[weighted_ext_score2]])) -> 360000 | Q9: =IF(Данные[[#This Row],[days_employed]]<$Q$1,MIN(Данные[[#This Row],[annuity_to_income]]*$Q$2,$C$2),IF(Данные[[#This Row],[days_employed]]<$Q$3,Данные[[#This Row],[annuity_to_income]]*$Q$4,IF(Данные[[#This Row],[days_employed]]=$Q$5,Данные[[#This Row],[annuity_to_income]]*$Q$6,Данные[[#This Row],[annuity_to_income]]))) -> 360000 | R9: =ABS(Данные[[#This Row],[days_birth]])/365.2425 -> 36.786519 | S9: =IF(Данные[[#This Row],[age_years]]<$S$1,Данные[[#This Row],[days_employed3]]*$S$2,IF(Данные[[#This Row],[age_years]]>$S$3,MIN(Данные[[#This Row],[days_employed3]]*$S$4,$C$2),Данные[[#This Row],[days_employed3]])) -> 360000 | T9: =IF(Данные[[#This Row],[ interest_rate]]>$T$1,Данные[[#This Row],[days_birth4]]*$T$2,Данные[[#This Row],[days_birth4]]) -> 360000 | U9: =IF(Данные[[#This Row],[Проверка отказа]]="отказ",0,MAX(Данные[[#This Row],[interest_rate]],$C$1)) -> 360000 | V9: =MROUND(Данные[[#This Row],[Минимум 20000]], 100) -> 360000 | X9: 360000 | Y9: =COUNTIF(Данные[Итоговая сумма], X9) -> 5 | Z9: =AVERAGEIF(Данные[Итоговая сумма], X9, Данные[proba]) -> 0.17133152 | AA9: =Y9*Z9 -> 0.8566576 | AB9: =Y9-AA9 -> 4.1433424 | AC9: =-X9*AA9*$Y$3 -> -308396.74 | AD9: =X9*AB9*$Y$4 -> 74580.163 | AE9: =AD9+AC9 -> -233816.57
A10: ='1000_заявлений'!A4 -> 2 | B10: =VALUE(SUBSTITUTE('1000_заявлений'!B4, ".", ",")) -> 0.20927631 | C10: =VALUE(SUBSTITUTE('1000_заявлений'!C4, ".", ",")) -> 0.66074064 | D10: =VALUE(SUBSTITUTE('1000_заявлений'!D4, ".", ",")) -> 0.66585493 | E10: =VALUE(SUBSTITUTE('1000_заявлений'!E4, ".", ",")) -> 0.41578013 | F10: =VALUE(SUBSTITUTE('1000_заявлений'!F4, ".", ",")) -> -9257 | G10: =VALUE(SUBSTITUTE('1000_заявлений'!G4, ".", ",")) -> -20066 | H10: =VALUE(SUBSTITUTE('1000_заявлений'!H4, ".", ",")) -> -3474 | I10: =VALUE(SUBSTITUTE('1000_заявлений'!I4, ".", ",")) -> 0.18545714 | ... L10: =VALUE(SUBSTITUTE('1000_заявлений'!L4, ".", ",")) -> 29209.5 | M10: =IF(Данные[[#This Row],[proba]]>$C$6, "отказ", "одобрение") -> одобрение | N10: =IF(Данные[[#This Row],[proba]]<$D$2,$C$2,IF(Данные[[#This Row],[proba]]<$D$3,$C$3,IF(Данные[[#This Row],[proba]]>$C$6,0,$C$4))) -> 100000 | O10: =IF(Данные[[#This Row],[weighted_ext_score]]>$O$1,MIN(Данные[[#This Row],[Базовая сумма]]*$O$2,$C$2),IF(Данные[[#This Row],[weighted_ext_score]]<$O$3,Данные[[#This Row],[Базовая сумма]]*$O$4,N10)) -> 100000 | P10: =IF(Данные[[#This Row],[ annuity_to_income_proportion]]>$P$1,Данные[[#This Row],[weighted_ext_score2]]*$P$2,IF(Данные[[#This Row],[ annuity_to_income_proportion]]<$P$3,MIN(Данные[[#This Row],[weighted_ext_score2]]*$P$4,$C$2),Данные[[#This Row],[weighted_ext_score2]])) -> 120000 | Q10: =IF(Данные[[#This Row],[days_employed]]<$Q$1,MIN(Данные[[#This Row],[annuity_to_income]]*$Q$2,$C$2),IF(Данные[[#This Row],[days_employed]]<$Q$3,Данные[[#This Row],[annuity_to_income]]*$Q$4,IF(Данные[[#This Row],[days_employed]]=$Q$5,Данные[[#This Row],[annuity_to_income]]*$Q$6,Данные[[#This Row],[annuity_to_income]]))) -> 120000 | R10: =ABS(Данные[[#This Row],[days_birth]])/365.2425 -> 54.938842 | S10: =IF(Данные[[#This Row],[age_years]]<$S$1,Данные[[#This Row],[days_employed3]]*$S$2,IF(Данные[[#This Row],[age_years]]>$S$3,MIN(Данные[[#This Row],[days_employed3]]*$S$4,$C$2),Данные[[#This Row],[days_employed3]])) -> 126000 | T10: =IF(Данные[[#This Row],[ interest_rate]]>$T$1,Данные[[#This Row],[days_birth4]]*$T$2,Данные[[#This Row],[days_birth4]]) -> 126000 | U10: =IF(Данные[[#This Row],[Проверка отказа]]="отказ",0,MAX(Данные[[#This Row],[interest_rate]],$C$1)) -> 126000 | V10: =MROUND(Данные[[#This Row],[Минимум 20000]], 100) -> 126000 | X10: 126000 | Y10: =COUNTIF(Данные[Итоговая сумма], X10) -> 33 | Z10: =AVERAGEIF(Данные[Итоговая сумма], X10, Данные[proba]) -> 0.24545361 | AA10: =Y10*Z10 -> 8.099969 | AB10: =Y10-AA10 -> 24.900031 | AC10: =-X10*AA10*$Y$3 -> -1020596.1 | AD10: =X10*AB10*$Y$4 -> 156870.2 | AE10: =AD10+AC10 -> -863725.9
A11: ='1000_заявлений'!A5 -> 3 | B11: =VALUE(SUBSTITUTE('1000_заявлений'!B5, ".", ",")) -> 0.66612597 | C11: =VALUE(SUBSTITUTE('1000_заявлений'!C5, ".", ",")) -> 0.22551354 | D11: =VALUE(SUBSTITUTE('1000_заявлений'!D5, ".", ",")) -> 0.53527623 | E11: =VALUE(SUBSTITUTE('1000_заявлений'!E5, ".", ",")) -> 0.26651978 | F11: =VALUE(SUBSTITUTE('1000_заявлений'!F5, ".", ",")) -> -4957 | G11: =VALUE(SUBSTITUTE('1000_заявлений'!G5, ".", ",")) -> -16953 | H11: =VALUE(SUBSTITUTE('1000_заявлений'!H5, ".", ",")) -> -510 | I11: =VALUE(SUBSTITUTE('1000_заявлений'!I5, ".", ",")) -> 0.20924 | ... L11: =VALUE(SUBSTITUTE('1000_заявлений'!L5, ".", ",")) -> 23539.5 | M11: =IF(Данные[[#This Row],[proba]]>$C$6, "отказ", "одобрение") -> отказ | N11: =IF(Данные[[#This Row],[proba]]<$D$2,$C$2,IF(Данные[[#This Row],[proba]]<$D$3,$C$3,IF(Данные[[#This Row],[proba]]>$C$6,0,$C$4))) -> 0 | O11: =IF(Данные[[#This Row],[weighted_ext_score]]>$O$1,MIN(Данные[[#This Row],[Базовая сумма]]*$O$2,$C$2),IF(Данные[[#This Row],[weighted_ext_score]]<$O$3,Данные[[#This Row],[Базовая сумма]]*$O$4,N11)) -> 0 | P11: =IF(Данные[[#This Row],[ annuity_to_income_proportion]]>$P$1,Данные[[#This Row],[weighted_ext_score2]]*$P$2,IF(Данные[[#This Row],[ annuity_to_income_proportion]]<$P$3,MIN(Данные[[#This Row],[weighted_ext_score2]]*$P$4,$C$2),Данные[[#This Row],[weighted_ext_score2]])) -> 0 | Q11: =IF(Данные[[#This Row],[days_employed]]<$Q$1,MIN(Данные[[#This Row],[annuity_to_income]]*$Q$2,$C$2),IF(Данные[[#This Row],[days_employed]]<$Q$3,Данные[[#This Row],[annuity_to_income]]*$Q$4,IF(Данные[[#This Row],[days_employed]]=$Q$5,Данные[[#This Row],[annuity_to_income]]*$Q$6,Данные[[#This Row],[annuity_to_income]]))) -> 0 | R11: =ABS(Данные[[#This Row],[days_birth]])/365.2425 -> 46.415737 | S11: =IF(Данные[[#This Row],[age_years]]<$S$1,Данные[[#This Row],[days_employed3]]*$S$2,IF(Данные[[#This Row],[age_years]]>$S$3,MIN(Данные[[#This Row],[days_employed3]]*$S$4,$C$2),Данные[[#This Row],[days_employed3]])) -> 0 | T11: =IF(Данные[[#This Row],[ interest_rate]]>$T$1,Данные[[#This Row],[days_birth4]]*$T$2,Данные[[#This Row],[days_birth4]]) -> 0 | U11: =IF(Данные[[#This Row],[Проверка отказа]]="отказ",0,MAX(Данные[[#This Row],[interest_rate]],$C$1)) -> 0 | V11: =MROUND(Данные[[#This Row],[Минимум 20000]], 100) -> 0 | X11: 58800 | Y11: =COUNTIF(Данные[Итоговая сумма], X11) -> 1 | Z11: =AVERAGEIF(Данные[Итоговая сумма], X11, Данные[proba]) -> 0.25154862 | AA11: =Y11*Z11 -> 0.25154862 | AB11: =Y11-AA11 -> 0.74845138 | AC11: =-X11*AA11*$Y$3 -> -14791.059 | AD11: =X11*AB11*$Y$4 -> 2200.4471 | AE11: =AD11+AC11 -> -12590.612
A12: ='1000_заявлений'!A6 -> 4 | B12: =VALUE(SUBSTITUTE('1000_заявлений'!B6, ".", ",")) -> 0.25154862 | C12: =VALUE(SUBSTITUTE('1000_заявлений'!C6, ".", ",")) -> 0.5031308 | D12: =VALUE(SUBSTITUTE('1000_заявлений'!D6, ".", ",")) -> 0.79226446 | E12: =VALUE(SUBSTITUTE('1000_заявлений'!E6, ".", ",")) -> 0.6677294 | F12: =VALUE(SUBSTITUTE('1000_заявлений'!F6, ".", ",")) -> -3208 | G12: =VALUE(SUBSTITUTE('1000_заявлений'!G6, ".", ",")) -> -9028 | H12: =VALUE(SUBSTITUTE('1000_заявлений'!H6, ".", ",")) -> -1695 | I12: =VALUE(SUBSTITUTE('1000_заявлений'!I6, ".", ",")) -> 0.16545 | ... L12: =VALUE(SUBSTITUTE('1000_заявлений'!L6, ".", ",")) -> 44671.5 | M12: =IF(Данные[[#This Row],[proba]]>$C$6, "отказ", "одобрение") -> одобрение | N12: =IF(Данные[[#This Row],[proba]]<$D$2,$C$2,IF(Данные[[#This Row],[proba]]<$D$3,$C$3,IF(Данные[[#This Row],[proba]]>$C$6,0,$C$4))) -> 100000 | O12: =IF(Данные[[#This Row],[weighted_ext_score]]>$O$1,MIN(Данные[[#This Row],[Базовая сумма]]*$O$2,$C$2),IF(Данные[[#This Row],[weighted_ext_score]]<$O$3,Данные[[#This Row],[Базовая сумма]]*$O$4,N12)) -> 100000 | P12: =IF(Данные[[#This Row],[ annuity_to_income_proportion]]>$P$1,Данные[[#This Row],[weighted_ext_score2]]*$P$2,IF(Данные[[#This Row],[ annuity_to_income_proportion]]<$P$3,MIN(Данные[[#This Row],[weighted_ext_score2]]*$P$4,$C$2),Данные[[#This Row],[weighted_ext_score2]])) -> 120000 | Q12: =IF(Данные[[#This Row],[days_employed]]<$Q$1,MIN(Данные[[#This Row],[annuity_to_income]]*$Q$2,$C$2),IF(Данные[[#This Row],[days_employed]]<$Q$3,Данные[[#This Row],[annuity_to_income]]*$Q$4,IF(Данные[[#This Row],[days_employed]]=$Q$5,Данные[[#This Row],[annuity_to_income]]*$Q$6,Данные[[#This Row],[annuity_to_income]]))) -> 84000 | R12: =ABS(Данные[[#This Row],[days_birth]])/365.2425 -> 24.717824 | S12: =IF(Данные[[#This Row],[age_years]]<$S$1,Данные[[#This Row],[days_employed3]]*$S$2,IF(Данные[[#This Row],[age_years]]>$S$3,MIN(Данные[[#This Row],[days_employed3]]*$S$4,$C$2),Данные[[#This Row],[days_employed3]])) -> 58800 | T12: =IF(Данные[[#This Row],[ interest_rate]]>$T$1,Данные[[#This Row],[days_birth4]]*$T$2,Данные[[#This Row],[days_birth4]]) -> 58800 | U12: =IF(Данные[[#This Row],[Проверка отказа]]="отказ",0,MAX(Данные[[#This Row],[interest_rate]],$C$1)) -> 58800 | V12: =MROUND(Данные[[#This Row],[Минимум 20000]], 100) -> 58800 | X12: 252000 | Y12: =COUNTIF(Данные[Итоговая сумма], X12) -> 8 | Z12: =AVERAGEIF(Данные[Итоговая сумма], X12, Данные[proba]) -> 0.18261062 | AA12: =Y12*Z12 -> 1.460885 | AB12: =Y12-AA12 -> 6.539115 | AC12: =-X12*AA12*$Y$3 -> -368143.01 | AD12: =X12*AB12*$Y$4 -> 82392.849 | AE12: =AD12+AC12 -> -285750.17
A13: ='1000_заявлений'!A7 -> 5 | B13: =VALUE(SUBSTITUTE('1000_заявлений'!B7, ".", ",")) -> 0.39294453 | C13: =VALUE(SUBSTITUTE('1000_заявлений'!C7, ".", ",")) -> 0.41816089 | D13: =VALUE(SUBSTITUTE('1000_заявлений'!D7, ".", ",")) -> 0.57620883 | E13: =VALUE(SUBSTITUTE('1000_заявлений'!E7, ".", ",")) -> 0.6466736 | F13: =VALUE(SUBSTITUTE('1000_заявлений'!F7, ".", ",")) -> -1976 | G13: =VALUE(SUBSTITUTE('1000_заявлений'!G7, ".", ",")) -> -17356 | H13: =VALUE(SUBSTITUTE('1000_заявлений'!H7, ".", ",")) -> -910 | I13: =VALUE(SUBSTITUTE('1000_заявлений'!I7, ".", ",")) -> 0.26674286 | ... L13: =VALUE(SUBSTITUTE('1000_заявлений'!L7, ".", ",")) -> 42012 | M13: =IF(Данные[[#This Row],[proba]]>$C$6, "отказ", "одобрение") -> отказ | N13: =IF(Данные[[#This Row],[proba]]<$D$2,$C$2,IF(Данные[[#This Row],[proba]]<$D$3,$C$3,IF(Данные[[#This Row],[proba]]>$C$6,0,$C$4))) -> 0 | O13: =IF(Данные[[#This Row],[weighted_ext_score]]>$O$1,MIN(Данные[[#This Row],[Базовая сумма]]*$O$2,$C$2),IF(Данные[[#This Row],[weighted_ext_score]]<$O$3,Данные[[#This Row],[Базовая сумма]]*$O$4,N13)) -> 0 | P13: =IF(Данные[[#This Row],[ annuity_to_income_proportion]]>$P$1,Данные[[#This Row],[weighted_ext_score2]]*$P$2,IF(Данные[[#This Row],[ annuity_to_income_proportion]]<$P$3,MIN(Данные[[#This Row],[weighted_ext_score2]]*$P$4,$C$2),Данные[[#This Row],[weighted_ext_score2]])) -> 0 | Q13: =IF(Данные[[#This Row],[days_employed]]<$Q$1,MIN(Данные[[#This Row],[annuity_to_income]]*$Q$2,$C$2),IF(Данные[[#This Row],[days_employed]]<$Q$3,Данные[[#This Row],[annuity_to_income]]*$Q$4,IF(Данные[[#This Row],[days_employed]]=$Q$5,Данные[[#This Row],[annuity_to_income]]*$Q$6,Данные[[#This Row],[annuity_to_income]]))) -> 0 | R13: =ABS(Данные[[#This Row],[days_birth]])/365.2425 -> 47.519114 | S13: =IF(Данные[[#This Row],[age_years]]<$S$1,Данные[[#This Row],[days_employed3]]*$S$2,IF(Данные[[#This Row],[age_years]]>$S$3,MIN(Данные[[#This Row],[days_employed3]]*$S$4,$C$2),Данные[[#This Row],[days_employed3]])) -> 0 | T13: =IF(Данные[[#This Row],[ interest_rate]]>$T$1,Данные[[#This Row],[days_birth4]]*$T$2,Данные[[#This Row],[days_birth4]]) -> 0 | U13: =IF(Данные[[#This Row],[Проверка отказа]]="отказ",0,MAX(Данные[[#This Row],[interest_rate]],$C$1)) -> 0 | V13: =MROUND(Данные[[#This Row],[Минимум 20000]], 100) -> 0 | X13: 378000 | Y13: =COUNTIF(Данные[Итоговая сумма], X13) -> 23 | Z13: =AVERAGEIF(Данные[Итоговая сумма], X13, Данные[proba]) -> 0.16787906 | AA13: =Y13*Z13 -> 3.8612183 | AB13: =Y13-AA13 -> 19.138782 | AC13: =-X13*AA13*$Y$3 -> -1459540.5 | AD13: =X13*AB13*$Y$4 -> 361722.97 | AE13: =AD13+AC13 -> -1097817.6
A14: ='1000_заявлений'!A8 -> 6 | B14: =VALUE(SUBSTITUTE('1000_заявлений'!B8, ".", ",")) -> 0.65607736 | C14: =VALUE(SUBSTITUTE('1000_заявлений'!C8, ".", ",")) -> 0.22766903 | D14: =VALUE(SUBSTITUTE('1000_заявлений'!D8, ".", ",")) -> 0.6212263 | E14: =VALUE(SUBSTITUTE('1000_заявлений'!E8, ".", ",")) -> 0.0092263855 | F14: =VALUE(SUBSTITUTE('1000_заявлений'!F8, ".", ",")) -> -644 | G14: =VALUE(SUBSTITUTE('1000_заявлений'!G8, ".", ",")) -> -23233 | H14: =VALUE(SUBSTITUTE('1000_заявлений'!H8, ".", ",")) -> -4172 | I14: =VALUE(SUBSTITUTE('1000_заявлений'!I8, ".", ",")) -> 0.23025 | ... L14: =VALUE(SUBSTITUTE('1000_заявлений'!L8, ".", ",")) -> 33156 | M14: =IF(Данные[[#This Row],[proba]]>$C$6, "отказ", "одобрение") -> отказ | N14: =IF(Данные[[#This Row],[proba]]<$D$2,$C$2,IF(Данные[[#This Row],[proba]]<$D$3,$C$3,IF(Данные[[#This Row],[proba]]>$C$6,0,$C$4))) -> 0 | O14: =IF(Данные[[#This Row],[weighted_ext_score]]>$O$1,MIN(Данные[[#This Row],[Базовая сумма]]*$O$2,$C$2),IF(Данные[[#This Row],[weighted_ext_score]]<$O$3,Данные[[#This Row],[Базовая сумма]]*$O$4,N14)) -> 0 | P14: =IF(Данные[[#This Row],[ annuity_to_income_proportion]]>$P$1,Данные[[#This Row],[weighted_ext_score2]]*$P$2,IF(Данные[[#This Row],[ annuity_to_income_proportion]]<$P$3,MIN(Данные[[#This Row],[weighted_ext_score2]]*$P$4,$C$2),Данные[[#This Row],[weighted_ext_score2]])) -> 0 | Q14: =IF(Данные[[#This Row],[days_employed]]<$Q$1,MIN(Данные[[#This Row],[annuity_to_income]]*$Q$2,$C$2),IF(Данные[[#This Row],[days_employed]]<$Q$3,Данные[[#This Row],[annuity_to_income]]*$Q$4,IF(Данные[[#This Row],[days_employed]]=$Q$5,Данные[[#This Row],[annuity_to_income]]*$Q$6,Данные[[#This Row],[annuity_to_income]]))) -> 0 | R14: =ABS(Данные[[#This Row],[days_birth]])/365.2425 -> 63.609793 | S14: =IF(Данные[[#This Row],[age_years]]<$S$1,Данные[[#This Row],[days_employed3]]*$S$2,IF(Данные[[#This Row],[age_years]]>$S$3,MIN(Данные[[#This Row],[days_employed3]]*$S$4,$C$2),Данные[[#This Row],[days_employed3]])) -> 0 | T14: =IF(Данные[[#This Row],[ interest_rate]]>$T$1,Данные[[#This Row],[days_birth4]]*$T$2,Данные[[#This Row],[days_birth4]]) -> 0 | U14: =IF(Данные[[#This Row],[Проверка отказа]]="отказ",0,MAX(Данные[[#This Row],[interest_rate]],$C$1)) -> 0 | V14: =MROUND(Данные[[#This Row],[Минимум 20000]], 100) -> 0 | X14: 302400 | Y14: =COUNTIF(Данные[Итоговая сумма], X14) -> 5 | Z14: =AVERAGEIF(Данные[Итоговая сумма], X14, Данные[proba]) -> 0.14833565 | AA14: =Y14*Z14 -> 0.74167825 | AB14: =Y14-AA14 -> 4.2583217 | AC14: =-X14*AA14*$Y$3 -> -224283.5 | AD14: =X14*AB14*$Y$4 -> 64385.825 | AE14: =AD14+AC14 -> -159897.68
A15: ='1000_заявлений'!A9 -> 7 | B15: =VALUE(SUBSTITUTE('1000_заявлений'!B9, ".", ",")) -> 0.451551 | C15: =VALUE(SUBSTITUTE('1000_заявлений'!C9, ".", ",")) -> 0.35681979 | D15: =VALUE(SUBSTITUTE('1000_заявлений'!D9, ".", ",")) -> 0.4632753 | E15: =VALUE(SUBSTITUTE('1000_заявлений'!E9, ".", ",")) -> 0.583485 | F15: =VALUE(SUBSTITUTE('1000_заявлений'!F9, ".", ",")) -> -7970 | G15: =VALUE(SUBSTITUTE('1000_заявлений'!G9, ".", ",")) -> -18719 | H15: =VALUE(SUBSTITUTE('1000_заявлений'!H9, ".", ",")) -> -2278 | I15: =VALUE(SUBSTITUTE('1000_заявлений'!I9, ".", ",")) -> 0.1711 | ... L15: =VALUE(SUBSTITUTE('1000_заявлений'!L9, ".", ",")) -> 15399 | M15: =IF(Данные[[#This Row],[proba]]>$C$6, "отказ", "одобрение") -> отказ | N15: =IF(Данные[[#This Row],[proba]]<$D$2,$C$2,IF(Данные[[#This Row],[proba]]<$D$3,$C$3,IF(Данные[[#This Row],[proba]]>$C$6,0,$C$4))) -> 0 | O15: =IF(Данные[[#This Row],[weighted_ext_score]]>$O$1,MIN(Данные[[#This Row],[Базовая сумма]]*$O$2,$C$2),IF(Данные[[#This Row],[weighted_ext_score]]<$O$3,Данные[[#This Row],[Базовая сумма]]*$O$4,N15)) -> 0 | P15: =IF(Данные[[#This Row],[ annuity_to_income_proportion]]>$P$1,Данные[[#This Row],[weighted_ext_score2]]*$P$2,IF(Данные[[#This Row],[ annuity_to_income_proportion]]<$P$3,MIN(Данные[[#This Row],[weighted_ext_score2]]*$P$4,$C$2),Данные[[#This Row],[weighted_ext_score2]])) -> 0 | Q15: =IF(Данные[[#This Row],[days_employed]]<$Q$1,MIN(Данные[[#This Row],[annuity_to_income]]*$Q$2,$C$2),IF(Данные[[#This Row],[days_employed]]<$Q$3,Данные[[#This Row],[annuity_to_income]]*$Q$4,IF(Данные[[#This Row],[days_employed]]=$Q$5,Данные[[#This Row],[annuity_to_income]]*$Q$6,Данные[[#This Row],[annuity_to_income]]))) -> 0 | R15: =ABS(Данные[[#This Row],[days_birth]])/365.2425 -> 51.250881 | S15: =IF(Данные[[#This Row],[age_years]]<$S$1,Данные[[#This Row],[days_employed3]]*$S$2,IF(Данные[[#This Row],[age_years]]>$S$3,MIN(Данные[[#This Row],[days_employed3]]*$S$4,$C$2),Данные[[#This Row],[days_employed3]])) -> 0 | T15: =IF(Данные[[#This Row],[ interest_rate]]>$T$1,Данные[[#This Row],[days_birth4]]*$T$2,Данные[[#This Row],[days_birth4]]) -> 0 | U15: =IF(Данные[[#This Row],[Проверка отказа]]="отказ",0,MAX(Данные[[#This Row],[interest_rate]],$C$1)) -> 0 | V15: =MROUND(Данные[[#This Row],[Минимум 20000]], 100) -> 0 | X15: 67200 | Y15: =COUNTIF(Данные[Итоговая сумма], X15) -> 1 | Z15: =AVERAGEIF(Данные[Итоговая сумма], X15, Данные[proba]) -> 0.28797515 | AA15: =Y15*Z15 -> 0.28797515 | AB15: =Y15-AA15 -> 0.71202485 | AC15: =-X15*AA15*$Y$3 -> -19351.93 | AD15: =X15*AB15*$Y$4 -> 2392.4035 | AE15: =AD15+AC15 -> -16959.526
A16: ='1000_заявлений'!A10 -> 8 | B16: =VALUE(SUBSTITUTE('1000_заявлений'!B10, ".", ",")) -> 0.19779022 | C16: =VALUE(SUBSTITUTE('1000_заявлений'!C10, ".", ",")) -> 0.49782097 | D16: =VALUE(SUBSTITUTE('1000_заявлений'!D10, ".", ",")) -> 0.7517237 | E16: =VALUE(SUBSTITUTE('1000_заявлений'!E10, ".", ",")) -> 0.6965612 | F16: =VALUE(SUBSTITUTE('1000_заявлений'!F10, ".", ",")) -> -2639 | G16: =VALUE(SUBSTITUTE('1000_заявлений'!G10, ".", ",")) -> -14817 | H16: =VALUE(SUBSTITUTE('1000_заявлений'!H10, ".", ",")) -> -4892 | I16: =VALUE(SUBSTITUTE('1000_заявлений'!I10, ".", ",")) -> 0.036546667 | ... L16: =VALUE(SUBSTITUTE('1000_заявлений'!L10, ".", ",")) -> 12334.5 | M16: =IF(Данные[[#This Row],[proba]]>$C$6, "отказ", "одобрение") -> одобрение | N16: =IF(Данные[[#This Row],[proba]]<$D$2,$C$2,IF(Данные[[#This Row],[proba]]<$D$3,$C$3,IF(Данные[[#This Row],[proba]]>$C$6,0,$C$4))) -> 300000 | O16: =IF(Данные[[#This Row],[weighted_ext_score]]>$O$1,MIN(Данные[[#This Row],[Базовая сумма]]*$O$2,$C$2),IF(Данные[[#This Row],[weighted_ext_score]]<$O$3,Данные[[#This Row],[Базовая сумма]]*$O$4,N16)) -> 300000 | P16: =IF(Данные[[#This Row],[ annuity_to_income_proportion]]>$P$1,Данные[[#This Row],[weighted_ext_score2]]*$P$2,IF(Данные[[#This Row],[ annuity_to_income_proportion]]<$P$3,MIN(Данные[[#This Row],[weighted_ext_score2]]*$P$4,$C$2),Данные[[#This Row],[weighted_ext_score2]])) -> 360000 | Q16: =IF(Данные[[#This Row],[days_employed]]<$Q$1,MIN(Данные[[#This Row],[annuity_to_income]]*$Q$2,$C$2),IF(Данные[[#This Row],[days_employed]]<$Q$3,Данные[[#This Row],[annuity_to_income]]*$Q$4,IF(Данные[[#This Row],[days_employed]]=$Q$5,Данные[[#This Row],[annuity_to_income]]*$Q$6,Данные[[#This Row],[annuity_to_income]]))) -> 252000 | R16: =ABS(Данные[[#This Row],[days_birth]])/365.2425 -> 40.567568 | S16: =IF(Данные[[#This Row],[age_years]]<$S$1,Данные[[#This Row],[days_employed3]]*$S$2,IF(Данные[[#This Row],[age_years]]>$S$3,MIN(Данные[[#This Row],[days_employed3]]*$S$4,$C$2),Данные[[#This Row],[days_employed3]])) -> 252000 | T16: =IF(Данные[[#This Row],[ interest_rate]]>$T$1,Данные[[#This Row],[days_birth4]]*$T$2,Данные[[#This Row],[days_birth4]]) -> 252000 | U16: =IF(Данные[[#This Row],[Проверка отказа]]="отказ",0,MAX(Данные[[#This Row],[interest_rate]],$C$1)) -> 252000 | V16: =MROUND(Данные[[#This Row],[Минимум 20000]], 100) -> 252000 | X16: 84000 | Y16: =COUNTIF(Данные[Итоговая сумма], X16) -> 28 | Z16: =AVERAGEIF(Данные[Итоговая сумма], X16, Данные[proba]) -> 0.24763287 | AA16: =Y16*Z16 -> 6.9337205 | AB16: =Y16-AA16 -> 21.06628 | AC16: =-X16*AA16*$Y$3 -> -582432.52 | AD16: =X16*AB16*$Y$4 -> 88478.374 | AE16: =AD16+AC16 -> -493954.15
A17: ='1000_заявлений'!A11 -> 9 | B17: =VALUE(SUBSTITUTE('1000_заявлений'!B11, ".", ",")) -> 0.42960218 | C17: =VALUE(SUBSTITUTE('1000_заявлений'!C11, ".", ",")) -> 0.35584775 | D17: =VALUE(SUBSTITUTE('1000_заявлений'!D11, ".", ",")) -> 0.7463002 | E17: =VALUE(SUBSTITUTE('1000_заявлений'!E11, ".", ",")) -> 0.2649283 | F17: =VALUE(SUBSTITUTE('1000_заявлений'!F11, ".", ",")) -> -4041 | G17: =VALUE(SUBSTITUTE('1000_заявлений'!G11, ".", ",")) -> -19962 | H17: =VALUE(SUBSTITUTE('1000_заявлений'!H11, ".", ",")) -> -3519 | I17: =VALUE(SUBSTITUTE('1000_заявлений'!I11, ".", ",")) -> 0.10825 | ... L17: =VALUE(SUBSTITUTE('1000_заявлений'!L11, ".", ",")) -> 9742.5 | M17: =IF(Данные[[#This Row],[proba]]>$C$6, "отказ", "одобрение") -> отказ | N17: =IF(Данные[[#This Row],[proba]]<$D$2,$C$2,IF(Данные[[#This Row],[proba]]<$D$3,$C$3,IF(Данные[[#This Row],[proba]]>$C$6,0,$C$4))) -> 0 | O17: =IF(Данные[[#This Row],[weighted_ext_score]]>$O$1,MIN(Данные[[#This Row],[Базовая сумма]]*$O$2,$C$2),IF(Данные[[#This Row],[weighted_ext_score]]<$O$3,Данные[[#This Row],[Базовая сумма]]*$O$4,N17)) -> 0 | P17: =IF(Данные[[#This Row],[ annuity_to_income_proportion]]>$P$1,Данные[[#This Row],[weighted_ext_score2]]*$P$2,IF(Данные[[#This Row],[ annuity_to_income_proportion]]<$P$3,MIN(Данные[[#This Row],[weighted_ext_score2]]*$P$4,$C$2),Данные[[#This Row],[weighted_ext_score2]])) -> 0 | Q17: =IF(Данные[[#This Row],[days_employed]]<$Q$1,MIN(Данные[[#This Row],[annuity_to_income]]*$Q$2,$C$2),IF(Данные[[#This Row],[days_employed]]<$Q$3,Данные[[#This Row],[annuity_to_income]]*$Q$4,IF(Данные[[#This Row],[days_employed]]=$Q$5,Данные[[#This Row],[annuity_to_income]]*$Q$6,Данные[[#This Row],[annuity_to_income]]))) -> 0 | R17: =ABS(Данные[[#This Row],[days_birth]])/365.2425 -> 54.6541 | S17: =IF(Данные[[#This Row],[age_years]]<$S$1,Данные[[#This Row],[days_employed3]]*$S$2,IF(Данные[[#This Row],[age_years]]>$S$3,MIN(Данные[[#This Row],[days_employed3]]*$S$4,$C$2),Данные[[#This Row],[days_employed3]])) -> 0 | T17: =IF(Данные[[#This Row],[ interest_rate]]>$T$1,Данные[[#This Row],[days_birth4]]*$T$2,Данные[[#This Row],[days_birth4]]) -> 0 | U17: =IF(Данные[[#This Row],[Проверка отказа]]="отказ",0,MAX(Данные[[#This Row],[interest_rate]],$C$1)) -> 0 | V17: =MROUND(Данные[[#This Row],[Минимум 20000]], 100) -> 0 | X17: 144000 | Y17: =COUNTIF(Данные[Итоговая сумма], X17) -> 44 | Z17: =AVERAGEIF(Данные[Итоговая сумма], X17, Данные[proba]) -> 0.25441 | AA17: =Y17*Z17 -> 11.19404 | AB17: =Y17-AA17 -> 32.80596 | AC17: =-X17*AA17*$Y$3 -> -1611941.8 | AD17: =X17*AB17*$Y$4 -> 236202.91 | AE17: =AD17+AC17 -> -1375738.9
A18: ='1000_заявлений'!A12 -> 10 | B18: =VALUE(SUBSTITUTE('1000_заявлений'!B12, ".", ",")) -> 0.7824465 | C18: =VALUE(SUBSTITUTE('1000_заявлений'!C12, ".", ",")) -> 0.35059184 | D18: =VALUE(SUBSTITUTE('1000_заявлений'!D12, ".", ",")) -> 0.21396685 | E18: =VALUE(SUBSTITUTE('1000_заявлений'!E12, ".", ",")) -> 0.25164637 | F18: =VALUE(SUBSTITUTE('1000_заявлений'!F12, ".", ",")) -> -1827 | G18: =VALUE(SUBSTITUTE('1000_заявлений'!G12, ".", ",")) -> -14908 | H18: =VALUE(SUBSTITUTE('1000_заявлений'!H12, ".", ",")) -> -1827 | I18: =VALUE(SUBSTITUTE('1000_заявлений'!I12, ".", ",")) -> 0.32666667 | ... L18: =VALUE(SUBSTITUTE('1000_заявлений'!L12, ".", ",")) -> 22050 | M18: =IF(Данные[[#This Row],[proba]]>$C$6, "отказ", "одобрение") -> отказ | N18: =IF(Данные[[#This Row],[proba]]<$D$2,$C$2,IF(Данные[[#This Row],[proba]]<$D$3,$C$3,IF(Данные[[#This Row],[proba]]>$C$6,0,$C$4))) -> 0 | O18: =IF(Данные[[#This Row],[weighted_ext_score]]>$O$1,MIN(Данные[[#This Row],[Базовая сумма]]*$O$2,$C$2),IF(Данные[[#This Row],[weighted_ext_score]]<$O$3,Данные[[#This Row],[Базовая сумма]]*$O$4,N18)) -> 0 | P18: =IF(Данные[[#This Row],[ annuity_to_income_proportion]]>$P$1,Данные[[#This Row],[weighted_ext_score2]]*$P$2,IF(Данные[[#This Row],[ annuity_to_income_proportion]]<$P$3,MIN(Данные[[#This Row],[weighted_ext_score2]]*$P$4,$C$2),Данные[[#This Row],[weighted_ext_score2]])) -> 0 | Q18: =IF(Данные[[#This Row],[days_employed]]<$Q$1,MIN(Данные[[#This Row],[annuity_to_income]]*$Q$2,$C$2),IF(Данные[[#This Row],[days_employed]]<$Q$3,Данные[[#This Row],[annuity_to_income]]*$Q$4,IF(Данные[[#This Row],[days_employed]]=$Q$5,Данные[[#This Row],[annuity_to_income]]*$Q$6,Данные[[#This Row],[annuity_to_income]]))) -> 0 | R18: =ABS(Данные[[#This Row],[days_birth]])/365.2425 -> 40.816718 | S18: =IF(Данные[[#This Row],[age_years]]<$S$1,Данные[[#This Row],[days_employed3]]*$S$2,IF(Данные[[#This Row],[age_years]]>$S$3,MIN(Данные[[#This Row],[days_employed3]]*$S$4,$C$2),Данные[[#This Row],[days_employed3]])) -> 0 | T18: =IF(Данные[[#This Row],[ interest_rate]]>$T$1,Данные[[#This Row],[days_birth4]]*$T$2,Данные[[#This Row],[days_birth4]]) -> 0 | U18: =IF(Данные[[#This Row],[Проверка отказа]]="отказ",0,MAX(Данные[[#This Row],[interest_rate]],$C$1)) -> 0 | V18: =MROUND(Данные[[#This Row],[Минимум 20000]], 100) -> 0 | X18: 432000 | Y18: =COUNTIF(Данные[Итоговая сумма], X18) -> 9 | Z18: =AVERAGEIF(Данные[Итоговая сумма], X18, Данные[proba]) -> 0.16869467 | AA18: =Y18*Z18 -> 1.518252 | AB18: =Y18-AA18 -> 7.481748 | AC18: =-X18*AA18*$Y$3 -> -655884.88 | AD18: =X18*AB18*$Y$4 -> 161605.76 | AE18: =AD18+AC18 -> -494279.13
A19: ='1000_заявлений'!A13 -> 11 | B19: =VALUE(SUBSTITUTE('1000_заявлений'!B13, ".", ",")) -> 0.68636461 | C19: =VALUE(SUBSTITUTE('1000_заявлений'!C13, ".", ",")) -> 0.34437115 | D19: =VALUE(SUBSTITUTE('1000_заявлений'!D13, ".", ",")) -> 0.30314636 | E19: =VALUE(SUBSTITUTE('1000_заявлений'!E13, ".", ",")) -> 0.41661963 | F19: =VALUE(SUBSTITUTE('1000_заявлений'!F13, ".", ",")) -> -3833 | G19: =VALUE(SUBSTITUTE('1000_заявлений'!G13, ".", ",")) -> -9400 | H19: =VALUE(SUBSTITUTE('1000_заявлений'!H13, ".", ",")) -> -1953 | I19: =VALUE(SUBSTITUTE('1000_заявлений'!I13, ".", ",")) -> 0.25902222 | ... L19: =VALUE(SUBSTITUTE('1000_заявлений'!L13, ".", ",")) -> 52452 | M19: =IF(Данные[[#This Row],[proba]]>$C$6, "отказ", "одобрение") -> отказ | N19: =IF(Данные[[#This Row],[proba]]<$D$2,$C$2,IF(Данные[[#This Row],[proba]]<$D$3,$C$3,IF(Данные[[#This Row],[proba]]>$C$6,0,$C$4))) -> 0 | O19: =IF(Данные[[#This Row],[weighted_ext_score]]>$O$1,MIN(Данные[[#This Row],[Базовая сумма]]*$O$2,$C$2),IF(Данные[[#This Row],[weighted_ext_score]]<$O$3,Данные[[#This Row],[Базовая сумма]]*$O$4,N19)) -> 0 | P19: =IF(Данные[[#This Row],[ annuity_to_income_proportion]]>$P$1,Данные[[#This Row],[weighted_ext_score2]]*$P$2,IF(Данные[[#This Row],[ annuity_to_income_proportion]]<$P$3,MIN(Данные[[#This Row],[weighted_ext_score2]]*$P$4,$C$2),Данные[[#This Row],[weighted_ext_score2]])) -> 0 | Q19: =IF(Данные[[#This Row],[days_employed]]<$Q$1,MIN(Данные[[#This Row],[annuity_to_income]]*$Q$2,$C$2),IF(Данные[[#This Row],[days_employed]]<$Q$3,Данные[[#This Row],[annuity_to_income]]*$Q$4,IF(Данные[[#This Row],[days_employed]]=$Q$5,Данные[[#This Row],[annuity_to_income]]*$Q$6,Данные[[#This Row],[annuity_to_income]]))) -> 0 | R19: =ABS(Данные[[#This Row],[days_birth]])/365.2425 -> 25.736326 | S19: =IF(Данные[[#This Row],[age_years]]<$S$1,Данные[[#This Row],[days_employed3]]*$S$2,IF(Данные[[#This Row],[age_years]]>$S$3,MIN(Данные[[#This Row],[days_employed3]]*$S$4,$C$2),Данные[[#This Row],[days_employed3]])) -> 0 | T19: =IF(Данные[[#This Row],[ interest_rate]]>$T$1,Данные[[#This Row],[days_birth4]]*$T$2,Данные[[#This Row],[days_birth4]]) -> 0 | U19: =IF(Данные[[#This Row],[Проверка отказа]]="отказ",0,MAX(Данные[[#This Row],[interest_rate]],$C$1)) -> 0 | V19: =MROUND(Данные[[#This Row],[Минимум 20000]], 100) -> 0 | X19: 453600 | Y19: =COUNTIF(Данные[Итоговая сумма], X19) -> 7 | Z19: =AVERAGEIF(Данные[Итоговая сумма], X19, Данные[proba]) -> 0.15381902 | AA19: =Y19*Z19 -> 1.0767331 | AB19: =Y19-AA19 -> 5.9232669 | AC19: =-X19*AA19*$Y$3 -> -488406.15 | AD19: =X19*AB19*$Y$4 -> 134339.69 | AE19: =AD19+AC19 -> -354066.46
A20: ='1000_заявлений'!A14 -> 12 | B20: =VALUE(SUBSTITUTE('1000_заявлений'!B14, ".", ",")) -> 0.52599306 | C20: =VALUE(SUBSTITUTE('1000_заявлений'!C14, ".", ",")) -> 0.47755893 | D20: =VALUE(SUBSTITUTE('1000_заявлений'!D14, ".", ",")) -> 0.09261717 | E20: =VALUE(SUBSTITUTE('1000_заявлений'!E14, ".", ",")) -> 0.6033201 | F20: =VALUE(SUBSTITUTE('1000_заявлений'!F14, ".", ",")) -> -2976 | G20: =VALUE(SUBSTITUTE('1000_заявлений'!G14, ".", ",")) -> -22336 | H20: =VALUE(SUBSTITUTE('1000_заявлений'!H14, ".", ",")) -> -992 | I20: =VALUE(SUBSTITUTE('1000_заявлений'!I14, ".", ",")) -> 0.1955641 | ... L20: =VALUE(SUBSTITUTE('1000_заявлений'!L14, ".", ",")) -> 68643 | M20: =IF(Данные[[#This Row],[proba]]>$C$6, "отказ", "одобрение") -> отказ | N20: =IF(Данные[[#This Row],[proba]]<$D$2,$C$2,IF(Данные[[#This Row],[proba]]<$D$3,$C$3,IF(Данные[[#This Row],[proba]]>$C$6,0,$C$4))) -> 0 | O20: =IF(Данные[[#This Row],[weighted_ext_score]]>$O$1,MIN(Данные[[#This Row],[Базовая сумма]]*$O$2,$C$2),IF(Данные[[#This Row],[weighted_ext_score]]<$O$3,Данные[[#This Row],[Базовая сумма]]*$O$4,N20)) -> 0 | P20: =IF(Данные[[#This Row],[ annuity_to_income_proportion]]>$P$1,Данные[[#This Row],[weighted_ext_score2]]*$P$2,IF(Данные[[#This Row],[ annuity_to_income_proportion]]<$P$3,MIN(Данные[[#This Row],[weighted_ext_score2]]*$P$4,$C$2),Данные[[#This Row],[weighted_ext_score2]])) -> 0 | Q20: =IF(Данные[[#This Row],[days_employed]]<$Q$1,MIN(Данные[[#This Row],[annuity_to_income]]*$Q$2,$C$2),IF(Данные[[#This Row],[days_employed]]<$Q$3,Данные[[#This Row],[annuity_to_income]]*$Q$4,IF(Данные[[#This Row],[days_employed]]=$Q$5,Данные[[#This Row],[annuity_to_income]]*$Q$6,Данные[[#This Row],[annuity_to_income]]))) -> 0 | R20: =ABS(Данные[[#This Row],[days_birth]])/365.2425 -> 61.153891 | S20: =IF(Данные[[#This Row],[age_years]]<$S$1,Данные[[#This Row],[days_employed3]]*$S$2,IF(Данные[[#This Row],[age_years]]>$S$3,MIN(Данные[[#This Row],[days_employed3]]*$S$4,$C$2),Данные[[#This Row],[days_employed3]])) -> 0 | T20: =IF(Данные[[#This Row],[ interest_rate]]>$T$1,Данные[[#This Row],[days_birth4]]*$T$2,Данные[[#This Row],[days_birth4]]) -> 0 | U20: =IF(Данные[[#This Row],[Проверка отказа]]="отказ",0,MAX(Данные[[#This Row],[interest_rate]],$C$1)) -> 0 | V20: =MROUND(Данные[[#This Row],[Минимум 20000]], 100) -> 0 | X20: 151200 | Y20: =COUNTIF(Данные[Итоговая сумма], X20) -> 14 | Z20: =AVERAGEIF(Данные[Итоговая сумма], X20, Данные[proba]) -> 0.25942858 | AA20: =Y20*Z20 -> 3.6320001 | AB20: =Y20-AA20 -> 10.368 | AC20: =-X20*AA20*$Y$3 -> -549158.41 | AD20: =X20*AB20*$Y$4 -> 78382.079 | AE20: =AD20+AC20 -> -470776.33
... A34: ='1000_заявлений'!A28 -> 26 | B34: =VALUE(SUBSTITUTE('1000_заявлений'!B28, ".", ",")) -> 0.41938894 | C34: =VALUE(SUBSTITUTE('1000_заявлений'!C28, ".", ",")) -> 0.50972748 | D34: =VALUE(SUBSTITUTE('1000_заявлений'!D28, ".", ",")) -> 0.7688076 | E34: =VALUE(SUBSTITUTE('1000_заявлений'!E28, ".", ",")) -> 0.20162591 | F34: =VALUE(SUBSTITUTE('1000_заявлений'!F28, ".", ",")) -> -2657 | G34: =VALUE(SUBSTITUTE('1000_заявлений'!G28, ".", ",")) -> -16228 | H34: =VALUE(SUBSTITUTE('1000_заявлений'!H28, ".", ",")) -> -2385 | I34: =VALUE(SUBSTITUTE('1000_заявлений'!I28, ".", ",")) -> 0.31926667 | ... L34: =VALUE(SUBSTITUTE('1000_заявлений'!L28, ".", ",")) -> 43101 | M34: =IF(Данные[[#This Row],[proba]]>$C$6, "отказ", "одобрение") -> отказ | N34: =IF(Данные[[#This Row],[proba]]<$D$2,$C$2,IF(Данные[[#This Row],[proba]]<$D$3,$C$3,IF(Данные[[#This Row],[proba]]>$C$6,0,$C$4))) -> 0 | O34: =IF(Данные[[#This Row],[weighted_ext_score]]>$O$1,MIN(Данные[[#This Row],[Базовая сумма]]*$O$2,$C$2),IF(Данные[[#This Row],[weighted_ext_score]]<$O$3,Данные[[#This Row],[Базовая сумма]]*$O$4,N34)) -> 0 | P34: =IF(Данные[[#This Row],[ annuity_to_income_proportion]]>$P$1,Данные[[#This Row],[weighted_ext_score2]]*$P$2,IF(Данные[[#This Row],[ annuity_to_income_proportion]]<$P$3,MIN(Данные[[#This Row],[weighted_ext_score2]]*$P$4,$C$2),Данные[[#This Row],[weighted_ext_score2]])) -> 0 | Q34: =IF(Данные[[#This Row],[days_employed]]<$Q$1,MIN(Данные[[#This Row],[annuity_to_income]]*$Q$2,$C$2),IF(Данные[[#This Row],[days_employed]]<$Q$3,Данные[[#This Row],[annuity_to_income]]*$Q$4,IF(Данные[[#This Row],[days_employed]]=$Q$5,Данные[[#This Row],[annuity_to_income]]*$Q$6,Данные[[#This Row],[annuity_to_income]]))) -> 0 | R34: =ABS(Данные[[#This Row],[days_birth]])/365.2425 -> 44.430755 | S34: =IF(Данные[[#This Row],[age_years]]<$S$1,Данные[[#This Row],[days_employed3]]*$S$2,IF(Данные[[#This Row],[age_years]]>$S$3,MIN(Данные[[#This Row],[days_employed3]]*$S$4,$C$2),Данные[[#This Row],[days_employed3]])) -> 0 | T34: =IF(Данные[[#This Row],[ interest_rate]]>$T$1,Данные[[#This Row],[days_birth4]]*$T$2,Данные[[#This Row],[days_birth4]]) -> 0 | U34: =IF(Данные[[#This Row],[Проверка отказа]]="отказ",0,MAX(Данные[[#This Row],[interest_rate]],$C$1)) -> 0 | V34: =MROUND(Данные[[#This Row],[Минимум 20000]], 100) -> 0 | X34: 70600 | Y34: =COUNTIF(Данные[Итоговая сумма], X34) -> 1 | Z34: =AVERAGEIF(Данные[Итоговая сумма], X34, Данные[proba]) -> 0.22696465 | AA34: =Y34*Z34 -> 0.22696465 | AB34: =Y34-AA34 -> 0.77303535 | AC34: =-X34*AA34*$Y$3 -> -16023.704 | AD34: =X34*AB34*$Y$4 -> 2728.8148 | AE34: =AD34+AC34 -> -13294.889
A35: ='1000_заявлений'!A29 -> 27 | B35: =VALUE(SUBSTITUTE('1000_заявлений'!B29, ".", ",")) -> 0.42744541 | C35: =VALUE(SUBSTITUTE('1000_заявлений'!C29, ".", ",")) -> 0.36469848 | D35: =VALUE(SUBSTITUTE('1000_заявлений'!D29, ".", ",")) -> 0.80045134 | E35: =VALUE(SUBSTITUTE('1000_заявлений'!E29, ".", ",")) -> 0.23183757 | F35: =VALUE(SUBSTITUTE('1000_заявлений'!F29, ".", ",")) -> -2901 | G35: =VALUE(SUBSTITUTE('1000_заявлений'!G29, ".", ",")) -> -17125 | H35: =VALUE(SUBSTITUTE('1000_заявлений'!H29, ".", ",")) -> -686 | I35: =VALUE(SUBSTITUTE('1000_заявлений'!I29, ".", ",")) -> 0.087466667 | ... L35: =VALUE(SUBSTITUTE('1000_заявлений'!L29, ".", ",")) -> 29520 | M35: =IF(Данные[[#This Row],[proba]]>$C$6, "отказ", "одобрение") -> отказ | N35: =IF(Данные[[#This Row],[proba]]<$D$2,$C$2,IF(Данные[[#This Row],[proba]]<$D$3,$C$3,IF(Данные[[#This Row],[proba]]>$C$6,0,$C$4))) -> 0 | O35: =IF(Данные[[#This Row],[weighted_ext_score]]>$O$1,MIN(Данные[[#This Row],[Базовая сумма]]*$O$2,$C$2),IF(Данные[[#This Row],[weighted_ext_score]]<$O$3,Данные[[#This Row],[Базовая сумма]]*$O$4,N35)) -> 0 | P35: =IF(Данные[[#This Row],[ annuity_to_income_proportion]]>$P$1,Данные[[#This Row],[weighted_ext_score2]]*$P$2,IF(Данные[[#This Row],[ annuity_to_income_proportion]]<$P$3,MIN(Данные[[#This Row],[weighted_ext_score2]]*$P$4,$C$2),Данные[[#This Row],[weighted_ext_score2]])) -> 0 | Q35: =IF(Данные[[#This Row],[days_employed]]<$Q$1,MIN(Данные[[#This Row],[annuity_to_income]]*$Q$2,$C$2),IF(Данные[[#This Row],[days_employed]]<$Q$3,Данные[[#This Row],[annuity_to_income]]*$Q$4,IF(Данные[[#This Row],[days_employed]]=$Q$5,Данные[[#This Row],[annuity_to_income]]*$Q$6,Данные[[#This Row],[annuity_to_income]]))) -> 0 | R35: =ABS(Данные[[#This Row],[days_birth]])/365.2425 -> 46.886657 | S35: =IF(Данные[[#This Row],[age_years]]<$S$1,Данные[[#This Row],[days_employed3]]*$S$2,IF(Данные[[#This Row],[age_years]]>$S$3,MIN(Данные[[#This Row],[days_employed3]]*$S$4,$C$2),Данные[[#This Row],[days_employed3]])) -> 0 | T35: =IF(Данные[[#This Row],[ interest_rate]]>$T$1,Данные[[#This Row],[days_birth4]]*$T$2,Данные[[#This Row],[days_birth4]]) -> 0 | U35: =IF(Данные[[#This Row],[Проверка отказа]]="отказ",0,MAX(Данные[[#This Row],[interest_rate]],$C$1)) -> 0 | V35: =MROUND(Данные[[#This Row],[Минимум 20000]], 100) -> 0
A36: ='1000_заявлений'!A30 -> 28 | B36: =VALUE(SUBSTITUTE('1000_заявлений'!B30, ".", ",")) -> 0.69417861 | C36: =VALUE(SUBSTITUTE('1000_заявлений'!C30, ".", ",")) -> 0.3372282 | D36: =VALUE(SUBSTITUTE('1000_заявлений'!D30, ".", ",")) -> 0.24054141 | E36: =VALUE(SUBSTITUTE('1000_заявлений'!E30, ".", ",")) -> 0.372698 | F36: =VALUE(SUBSTITUTE('1000_заявлений'!F30, ".", ",")) -> -5263 | G36: =VALUE(SUBSTITUTE('1000_заявлений'!G30, ".", ",")) -> -12471 | H36: =VALUE(SUBSTITUTE('1000_заявлений'!H30, ".", ",")) -> -2988 | I36: =VALUE(SUBSTITUTE('1000_заявлений'!I30, ".", ",")) -> 0.175725 | ... L36: =VALUE(SUBSTITUTE('1000_заявлений'!L30, ".", ",")) -> 31630.5 | M36: =IF(Данные[[#This Row],[proba]]>$C$6, "отказ", "одобрение") -> отказ | N36: =IF(Данные[[#This Row],[proba]]<$D$2,$C$2,IF(Данные[[#This Row],[proba]]<$D$3,$C$3,IF(Данные[[#This Row],[proba]]>$C$6,0,$C$4))) -> 0 | O36: =IF(Данные[[#This Row],[weighted_ext_score]]>$O$1,MIN(Данные[[#This Row],[Базовая сумма]]*$O$2,$C$2),IF(Данные[[#This Row],[weighted_ext_score]]<$O$3,Данные[[#This Row],[Базовая сумма]]*$O$4,N36)) -> 0 | P36: =IF(Данные[[#This Row],[ annuity_to_income_proportion]]>$P$1,Данные[[#This Row],[weighted_ext_score2]]*$P$2,IF(Данные[[#This Row],[ annuity_to_income_proportion]]<$P$3,MIN(Данные[[#This Row],[weighted_ext_score2]]*$P$4,$C$2),Данные[[#This Row],[weighted_ext_score2]])) -> 0 | Q36: =IF(Данные[[#This Row],[days_employed]]<$Q$1,MIN(Данные[[#This Row],[annuity_to_income]]*$Q$2,$C$2),IF(Данные[[#This Row],[days_employed]]<$Q$3,Данные[[#This Row],[annuity_to_income]]*$Q$4,IF(Данные[[#This Row],[days_employed]]=$Q$5,Данные[[#This Row],[annuity_to_income]]*$Q$6,Данные[[#This Row],[annuity_to_income]]))) -> 0 | R36: =ABS(Данные[[#This Row],[days_birth]])/365.2425 -> 34.144438 | S36: =IF(Данные[[#This Row],[age_years]]<$S$1,Данные[[#This Row],[days_employed3]]*$S$2,IF(Данные[[#This Row],[age_years]]>$S$3,MIN(Данные[[#This Row],[days_employed3]]*$S$4,$C$2),Данные[[#This Row],[days_employed3]])) -> 0 | T36: =IF(Данные[[#This Row],[ interest_rate]]>$T$1,Данные[[#This Row],[days_birth4]]*$T$2,Данные[[#This Row],[days_birth4]]) -> 0 | U36: =IF(Данные[[#This Row],[Проверка отказа]]="отказ",0,MAX(Данные[[#This Row],[interest_rate]],$C$1)) -> 0 | V36: =MROUND(Данные[[#This Row],[Минимум 20000]], 100) -> 0
A37: ='1000_заявлений'!A31 -> 29 | B37: =VALUE(SUBSTITUTE('1000_заявлений'!B31, ".", ",")) -> 0.49802235 | C37: =VALUE(SUBSTITUTE('1000_заявлений'!C31, ".", ",")) -> 0.330483 | D37: =VALUE(SUBSTITUTE('1000_заявлений'!D31, ".", ",")) -> 0.24585122 | E37: =VALUE(SUBSTITUTE('1000_заявлений'!E31, ".", ",")) -> 0.7447111 | F37: =VALUE(SUBSTITUTE('1000_заявлений'!F31, ".", ",")) -> -1903 | G37: =VALUE(SUBSTITUTE('1000_заявлений'!G31, ".", ",")) -> -21717 | H37: =VALUE(SUBSTITUTE('1000_заявлений'!H31, ".", ",")) -> -4150 | I37: =VALUE(SUBSTITUTE('1000_заявлений'!I31, ".", ",")) -> 0.12915556 | ... L37: =VALUE(SUBSTITUTE('1000_заявлений'!L31, ".", ",")) -> 26154 | M37: =IF(Данные[[#This Row],[proba]]>$C$6, "отказ", "одобрение") -> отказ | N37: =IF(Данные[[#This Row],[proba]]<$D$2,$C$2,IF(Данные[[#This Row],[proba]]<$D$3,$C$3,IF(Данные[[#This Row],[proba]]>$C$6,0,$C$4))) -> 0 | O37: =IF(Данные[[#This Row],[weighted_ext_score]]>$O$1,MIN(Данные[[#This Row],[Базовая сумма]]*$O$2,$C$2),IF(Данные[[#This Row],[weighted_ext_score]]<$O$3,Данные[[#This Row],[Базовая сумма]]*$O$4,N37)) -> 0 | P37: =IF(Данные[[#This Row],[ annuity_to_income_proportion]]>$P$1,Данные[[#This Row],[weighted_ext_score2]]*$P$2,IF(Данные[[#This Row],[ annuity_to_income_proportion]]<$P$3,MIN(Данные[[#This Row],[weighted_ext_score2]]*$P$4,$C$2),Данные[[#This Row],[weighted_ext_score2]])) -> 0 | Q37: =IF(Данные[[#This Row],[days_employed]]<$Q$1,MIN(Данные[[#This Row],[annuity_to_income]]*$Q$2,$C$2),IF(Данные[[#This Row],[days_employed]]<$Q$3,Данные[[#This Row],[annuity_to_income]]*$Q$4,IF(Данные[[#This Row],[days_employed]]=$Q$5,Данные[[#This Row],[annuity_to_income]]*$Q$6,Данные[[#This Row],[annuity_to_income]]))) -> 0 | R37: =ABS(Данные[[#This Row],[days_birth]])/365.2425 -> 59.459126 | S37: =IF(Данные[[#This Row],[age_years]]<$S$1,Данные[[#This Row],[days_employed3]]*$S$2,IF(Данные[[#This Row],[age_years]]>$S$3,MIN(Данные[[#This Row],[days_employed3]]*$S$4,$C$2),Данные[[#This Row],[days_employed3]])) -> 0 | T37: =IF(Данные[[#This Row],[ interest_rate]]>$T$1,Данные[[#This Row],[days_birth4]]*$T$2,Данные[[#This Row],[days_birth4]]) -> 0 | U37: =IF(Данные[[#This Row],[Проверка отказа]]="отказ",0,MAX(Данные[[#This Row],[interest_rate]],$C$1)) -> 0 | V37: =MROUND(Данные[[#This Row],[Минимум 20000]], 100) -> 0
A38: ='1000_заявлений'!A32 -> 30 | B38: =VALUE(SUBSTITUTE('1000_заявлений'!B32, ".", ",")) -> 0.72471809 | C38: =VALUE(SUBSTITUTE('1000_заявлений'!C32, ".", ",")) -> 0.18160691 | D38: =VALUE(SUBSTITUTE('1000_заявлений'!D32, ".", ",")) -> 0.35729328 | E38: =VALUE(SUBSTITUTE('1000_заявлений'!E32, ".", ",")) -> 0.16149798 | F38: =VALUE(SUBSTITUTE('1000_заявлений'!F32, ".", ",")) -> -5472 | G38: =VALUE(SUBSTITUTE('1000_заявлений'!G32, ".", ",")) -> -18034 | H38: =VALUE(SUBSTITUTE('1000_заявлений'!H32, ".", ",")) -> -1574 | I38: =VALUE(SUBSTITUTE('1000_заявлений'!I32, ".", ",")) -> 0.023433735 | ... L38: =VALUE(SUBSTITUTE('1000_заявлений'!L32, ".", ",")) -> 8752.5 | M38: =IF(Данные[[#This Row],[proba]]>$C$6, "отказ", "одобрение") -> отказ | N38: =IF(Данные[[#This Row],[proba]]<$D$2,$C$2,IF(Данные[[#This Row],[proba]]<$D$3,$C$3,IF(Данные[[#This Row],[proba]]>$C$6,0,$C$4))) -> 0 | O38: =IF(Данные[[#This Row],[weighted_ext_score]]>$O$1,MIN(Данные[[#This Row],[Базовая сумма]]*$O$2,$C$2),IF(Данные[[#This Row],[weighted_ext_score]]<$O$3,Данные[[#This Row],[Базовая сумма]]*$O$4,N38)) -> 0 | P38: =IF(Данные[[#This Row],[ annuity_to_income_proportion]]>$P$1,Данные[[#This Row],[weighted_ext_score2]]*$P$2,IF(Данные[[#This Row],[ annuity_to_income_proportion]]<$P$3,MIN(Данные[[#This Row],[weighted_ext_score2]]*$P$4,$C$2),Данные[[#This Row],[weighted_ext_score2]])) -> 0 | Q38: =IF(Данные[[#This Row],[days_employed]]<$Q$1,MIN(Данные[[#This Row],[annuity_to_income]]*$Q$2,$C$2),IF(Данные[[#This Row],[days_employed]]<$Q$3,Данные[[#This Row],[annuity_to_income]]*$Q$4,IF(Данные[[#This Row],[days_employed]]=$Q$5,Данные[[#This Row],[annuity_to_income]]*$Q$6,Данные[[#This Row],[annuity_to_income]]))) -> 0 | R38: =ABS(Данные[[#This Row],[days_birth]])/365.2425 -> 49.375415 | S38: =IF(Данные[[#This Row],[age_years]]<$S$1,Данные[[#This Row],[days_employed3]]*$S$2,IF(Данные[[#This Row],[age_years]]>$S$3,MIN(Данные[[#This Row],[days_employed3]]*$S$4,$C$2),Данные[[#This Row],[days_employed3]])) -> 0 | T38: =IF(Данные[[#This Row],[ interest_rate]]>$T$1,Данные[[#This Row],[days_birth4]]*$T$2,Данные[[#This Row],[days_birth4]]) -> 0 | U38: =IF(Данные[[#This Row],[Проверка отказа]]="отказ",0,MAX(Данные[[#This Row],[interest_rate]],$C$1)) -> 0 | V38: =MROUND(Данные[[#This Row],[Минимум 20000]], 100) -> 0
A39: ='1000_заявлений'!A33 -> 31 | B39: =VALUE(SUBSTITUTE('1000_заявлений'!B33, ".", ",")) -> 0.5276983 | C39: =VALUE(SUBSTITUTE('1000_заявлений'!C33, ".", ",")) -> 0.28545869 | D39: =VALUE(SUBSTITUTE('1000_заявлений'!D33, ".", ",")) -> 0.5513813 | E39: =VALUE(SUBSTITUTE('1000_заявлений'!E33, ".", ",")) -> 0.26525635 | F39: =VALUE(SUBSTITUTE('1000_заявлений'!F33, ".", ",")) -> -10927 | G39: =VALUE(SUBSTITUTE('1000_заявлений'!G33, ".", ",")) -> -22048 | H39: =VALUE(SUBSTITUTE('1000_заявлений'!H33, ".", ",")) -> -3997 | I39: =VALUE(SUBSTITUTE('1000_заявлений'!I33, ".", ",")) -> 0.2935 | ... L39: =VALUE(SUBSTITUTE('1000_заявлений'!L33, ".", ",")) -> 23773.5 | M39: =IF(Данные[[#This Row],[proba]]>$C$6, "отказ", "одобрение") -> отказ | N39: =IF(Данные[[#This Row],[proba]]<$D$2,$C$2,IF(Данные[[#This Row],[proba]]<$D$3,$C$3,IF(Данные[[#This Row],[proba]]>$C$6,0,$C$4))) -> 0 | O39: =IF(Данные[[#This Row],[weighted_ext_score]]>$O$1,MIN(Данные[[#This Row],[Базовая сумма]]*$O$2,$C$2),IF(Данные[[#This Row],[weighted_ext_score]]<$O$3,Данные[[#This Row],[Базовая сумма]]*$O$4,N39)) -> 0 | P39: =IF(Данные[[#This Row],[ annuity_to_income_proportion]]>$P$1,Данные[[#This Row],[weighted_ext_score2]]*$P$2,IF(Данные[[#This Row],[ annuity_to_income_proportion]]<$P$3,MIN(Данные[[#This Row],[weighted_ext_score2]]*$P$4,$C$2),Данные[[#This Row],[weighted_ext_score2]])) -> 0 | Q39: =IF(Данные[[#This Row],[days_employed]]<$Q$1,MIN(Данные[[#This Row],[annuity_to_income]]*$Q$2,$C$2),IF(Данные[[#This Row],[days_employed]]<$Q$3,Данные[[#This Row],[annuity_to_income]]*$Q$4,IF(Данные[[#This Row],[days_employed]]=$Q$5,Данные[[#This Row],[annuity_to_income]]*$Q$6,Данные[[#This Row],[annuity_to_income]]))) -> 0 | R39: =ABS(Данные[[#This Row],[days_birth]])/365.2425 -> 60.365374 | S39: =IF(Данные[[#This Row],[age_years]]<$S$1,Данные[[#This Row],[days_employed3]]*$S$2,IF(Данные[[#This Row],[age_years]]>$S$3,MIN(Данные[[#This Row],[days_employed3]]*$S$4,$C$2),Данные[[#This Row],[days_employed3]])) -> 0 | T39: =IF(Данные[[#This Row],[ interest_rate]]>$T$1,Данные[[#This Row],[days_birth4]]*$T$2,Данные[[#This Row],[days_birth4]]) -> 0 | U39: =IF(Данные[[#This Row],[Проверка отказа]]="отказ",0,MAX(Данные[[#This Row],[interest_rate]],$C$1)) -> 0 | V39: =MROUND(Данные[[#This Row],[Минимум 20000]], 100) -> 0
A40: ='1000_заявлений'!A34 -> 32 | B40: =VALUE(SUBSTITUTE('1000_заявлений'!B34, ".", ",")) -> 0.41946951 | C40: =VALUE(SUBSTITUTE('1000_заявлений'!C34, ".", ",")) -> 0.40136737 | D40: =VALUE(SUBSTITUTE('1000_заявлений'!D34, ".", ",")) -> 0.7062051 | E40: =VALUE(SUBSTITUTE('1000_заявлений'!E34, ".", ",")) -> 0.44996196 | F40: =VALUE(SUBSTITUTE('1000_заявлений'!F34, ".", ",")) -> -7239 | G40: =VALUE(SUBSTITUTE('1000_заявлений'!G34, ".", ",")) -> -13259 | H40: =VALUE(SUBSTITUTE('1000_заявлений'!H34, ".", ",")) -> -4117 | I40: =VALUE(SUBSTITUTE('1000_заявлений'!I34, ".", ",")) -> 0.34012 | ... L40: =VALUE(SUBSTITUTE('1000_заявлений'!L34, ".", ",")) -> 38263.5 | M40: =IF(Данные[[#This Row],[proba]]>$C$6, "отказ", "одобрение") -> отказ | N40: =IF(Данные[[#This Row],[proba]]<$D$2,$C$2,IF(Данные[[#This Row],[proba]]<$D$3,$C$3,IF(Данные[[#This Row],[proba]]>$C$6,0,$C$4))) -> 0 | O40: =IF(Данные[[#This Row],[weighted_ext_score]]>$O$1,MIN(Данные[[#This Row],[Базовая сумма]]*$O$2,$C$2),IF(Данные[[#This Row],[weighted_ext_score]]<$O$3,Данные[[#This Row],[Базовая сумма]]*$O$4,N40)) -> 0 | P40: =IF(Данные[[#This Row],[ annuity_to_income_proportion]]>$P$1,Данные[[#This Row],[weighted_ext_score2]]*$P$2,IF(Данные[[#This Row],[ annuity_to_income_proportion]]<$P$3,MIN(Данные[[#This Row],[weighted_ext_score2]]*$P$4,$C$2),Данные[[#This Row],[weighted_ext_score2]])) -> 0 | Q40: =IF(Данные[[#This Row],[days_employed]]<$Q$1,MIN(Данные[[#This Row],[annuity_to_income]]*$Q$2,$C$2),IF(Данные[[#This Row],[days_employed]]<$Q$3,Данные[[#This Row],[annuity_to_income]]*$Q$4,IF(Данные[[#This Row],[days_employed]]=$Q$5,Данные[[#This Row],[annuity_to_income]]*$Q$6,Данные[[#This Row],[annuity_to_income]]))) -> 0 | R40: =ABS(Данные[[#This Row],[days_birth]])/365.2425 -> 36.301909 | S40: =IF(Данные[[#This Row],[age_years]]<$S$1,Данные[[#This Row],[days_employed3]]*$S$2,IF(Данные[[#This Row],[age_years]]>$S$3,MIN(Данные[[#This Row],[days_employed3]]*$S$4,$C$2),Данные[[#This Row],[days_employed3]])) -> 0 | T40: =IF(Данные[[#This Row],[ interest_rate]]>$T$1,Данные[[#This Row],[days_birth4]]*$T$2,Данные[[#This Row],[days_birth4]]) -> 0 | U40: =IF(Данные[[#This Row],[Проверка отказа]]="отказ",0,MAX(Данные[[#This Row],[interest_rate]],$C$1)) -> 0 | V40: =MROUND(Данные[[#This Row],[Минимум 20000]], 100) -> 0
A41: ='1000_заявлений'!A35 -> 33 | B41: =VALUE(SUBSTITUTE('1000_заявлений'!B35, ".", ",")) -> 0.51344706 | C41: =VALUE(SUBSTITUTE('1000_заявлений'!C35, ".", ",")) -> 0.44097412 | D41: =VALUE(SUBSTITUTE('1000_заявлений'!D35, ".", ",")) -> 0.49386287 | E41: =VALUE(SUBSTITUTE('1000_заявлений'!E35, ".", ",")) -> 0.35322994 | F41: =VALUE(SUBSTITUTE('1000_заявлений'!F35, ".", ",")) -> -284 | G41: =VALUE(SUBSTITUTE('1000_заявлений'!G35, ".", ",")) -> -15895 | H41: =VALUE(SUBSTITUTE('1000_заявлений'!H35, ".", ",")) -> -4570 | I41: =VALUE(SUBSTITUTE('1000_заявлений'!I35, ".", ",")) -> 0.18888 | ... L41: =VALUE(SUBSTITUTE('1000_заявлений'!L35, ".", ",")) -> 42498 | M41: =IF(Данные[[#This Row],[proba]]>$C$6, "отказ", "одобрение") -> отказ | N41: =IF(Данные[[#This Row],[proba]]<$D$2,$C$2,IF(Данные[[#This Row],[proba]]<$D$3,$C$3,IF(Данные[[#This Row],[proba]]>$C$6,0,$C$4))) -> 0 | O41: =IF(Данные[[#This Row],[weighted_ext_score]]>$O$1,MIN(Данные[[#This Row],[Базовая сумма]]*$O$2,$C$2),IF(Данные[[#This Row],[weighted_ext_score]]<$O$3,Данные[[#This Row],[Базовая сумма]]*$O$4,N41)) -> 0 | P41: =IF(Данные[[#This Row],[ annuity_to_income_proportion]]>$P$1,Данные[[#This Row],[weighted_ext_score2]]*$P$2,IF(Данные[[#This Row],[ annuity_to_income_proportion]]<$P$3,MIN(Данные[[#This Row],[weighted_ext_score2]]*$P$4,$C$2),Данные[[#This Row],[weighted_ext_score2]])) -> 0 | Q41: =IF(Данные[[#This Row],[days_employed]]<$Q$1,MIN(Данные[[#This Row],[annuity_to_income]]*$Q$2,$C$2),IF(Данные[[#This Row],[days_employed]]<$Q$3,Данные[[#This Row],[annuity_to_income]]*$Q$4,IF(Данные[[#This Row],[days_employed]]=$Q$5,Данные[[#This Row],[annuity_to_income]]*$Q$6,Данные[[#This Row],[annuity_to_income]]))) -> 0 | R41: =ABS(Данные[[#This Row],[days_birth]])/365.2425 -> 43.519032 | S41: =IF(Данные[[#This Row],[age_years]]<$S$1,Данные[[#This Row],[days_employed3]]*$S$2,IF(Данные[[#This Row],[age_years]]>$S$3,MIN(Данные[[#This Row],[days_employed3]]*$S$4,$C$2),Данные[[#This Row],[days_employed3]])) -> 0 | T41: =IF(Данные[[#This Row],[ interest_rate]]>$T$1,Данные[[#This Row],[days_birth4]]*$T$2,Данные[[#This Row],[days_birth4]]) -> 0 | U41: =IF(Данные[[#This Row],[Проверка отказа]]="отказ",0,MAX(Данные[[#This Row],[interest_rate]],$C$1)) -> 0 | V41: =MROUND(Данные[[#This Row],[Минимум 20000]], 100) -> 0
A42: ='1000_заявлений'!A36 -> 34 | B42: =VALUE(SUBSTITUTE('1000_заявлений'!B36, ".", ",")) -> 0.2384468 | C42: =VALUE(SUBSTITUTE('1000_заявлений'!C36, ".", ",")) -> 0.62909307 | D42: =VALUE(SUBSTITUTE('1000_заявлений'!D36, ".", ",")) -> 0.5531647 | E42: =VALUE(SUBSTITUTE('1000_заявлений'!E36, ".", ",")) -> 0.6533645 | F42: =VALUE(SUBSTITUTE('1000_заявлений'!F36, ".", ",")) -> -7532 | G42: =VALUE(SUBSTITUTE('1000_заявлений'!G36, ".", ",")) -> -15913 | H42: =VALUE(SUBSTITUTE('1000_заявлений'!H36, ".", ",")) -> -3950 | I42: =VALUE(SUBSTITUTE('1000_заявлений'!I36, ".", ",")) -> 0.175 | ... L42: =VALUE(SUBSTITUTE('1000_заявлений'!L36, ".", ",")) -> 15750 | M42: =IF(Данные[[#This Row],[proba]]>$C$6, "отказ", "одобрение") -> одобрение | N42: =IF(Данные[[#This Row],[proba]]<$D$2,$C$2,IF(Данные[[#This Row],[proba]]<$D$3,$C$3,IF(Данные[[#This Row],[proba]]>$C$6,0,$C$4))) -> 100000 | O42: =IF(Данные[[#This Row],[weighted_ext_score]]>$O$1,MIN(Данные[[#This Row],[Базовая сумма]]*$O$2,$C$2),IF(Данные[[#This Row],[weighted_ext_score]]<$O$3,Данные[[#This Row],[Базовая сумма]]*$O$4,N42)) -> 100000 | P42: =IF(Данные[[#This Row],[ annuity_to_income_proportion]]>$P$1,Данные[[#This Row],[weighted_ext_score2]]*$P$2,IF(Данные[[#This Row],[ annuity_to_income_proportion]]<$P$3,MIN(Данные[[#This Row],[weighted_ext_score2]]*$P$4,$C$2),Данные[[#This Row],[weighted_ext_score2]])) -> 120000 | Q42: =IF(Данные[[#This Row],[days_employed]]<$Q$1,MIN(Данные[[#This Row],[annuity_to_income]]*$Q$2,$C$2),IF(Данные[[#This Row],[days_employed]]<$Q$3,Данные[[#This Row],[annuity_to_income]]*$Q$4,IF(Данные[[#This Row],[days_employed]]=$Q$5,Данные[[#This Row],[annuity_to_income]]*$Q$6,Данные[[#This Row],[annuity_to_income]]))) -> 144000 | R42: =ABS(Данные[[#This Row],[days_birth]])/365.2425 -> 43.568314 | S42: =IF(Данные[[#This Row],[age_years]]<$S$1,Данные[[#This Row],[days_employed3]]*$S$2,IF(Данные[[#This Row],[age_years]]>$S$3,MIN(Данные[[#This Row],[days_employed3]]*$S$4,$C$2),Данные[[#This Row],[days_employed3]])) -> 144000 | T42: =IF(Данные[[#This Row],[ interest_rate]]>$T$1,Данные[[#This Row],[days_birth4]]*$T$2,Данные[[#This Row],[days_birth4]]) -> 144000 | U42: =IF(Данные[[#This Row],[Проверка отказа]]="отказ",0,MAX(Данные[[#This Row],[interest_rate]],$C$1)) -> 144000 | V42: =MROUND(Данные[[#This Row],[Минимум 20000]], 100) -> 144000
